Workbook
Name valuevx: 42.314159
Name wld_az1_rack2_child_dns_zone: 'Value Reference Tables - MR'!#REF!
Name wld_az1_rack3_child_dns_zone: 'Value Reference Tables - MR'!#REF!
Name wld_az1_rack4_child_dns_zone: 'Value Reference Tables - MR'!#REF!
Name wld_az1_rack5_child_dns_zone: 'Value Reference Tables - MR'!#REF!
Name wld_az1_rack6_child_dns_zone: 'Value Reference Tables - MR'!#REF!
Name wld_az1_rack7_child_dns_zone: 'Value Reference Tables - MR'!#REF!
Name wld_az1_rack8_child_dns_zone: 'Value Reference Tables - MR'!#REF!
Name mgmt_stretched_cluster_result: 'Configure Management Domain'!$D$15
Name input_flt_custom_network_auto_nodeb_ip: 'Deploy Fleet Management Day-N'!$D$54
Name sample_wld_az1_rack4_host_overlay_vlan: 'Additional Racks'!$C$277
Name input_mgmt_ec01_en02_host_group_affinity_rule_name: 'Configure Management Domain'!$D$129
Name sizing_w01_vcenter_storage_size: 'Management Domain Sizing'!$F$36
Name input_mgmt_az1_uplink02_gateway_ip: 'Configure Management Domain'!$D$198
Name wld_az1_rack4_en1_uplink01_interface_ip: 'Value Reference Tables - MR'!$R$242
Name storage_autopolicy: 'Static Reference Tables'!$B$379
Name sample_wld_az1_rack6_edge_overlay_vlan: Arkham!$N$58
Name input_flt_auto_node_pool_end_ip: Arkham!$Q$35
Name wld_az1_rack3_edge_overlay_gateway_ip: 'Value Reference Tables - MR'!$O$94
Name input_wld_az1_rack6_pool_name: 'Additional Racks'!$D$406
Name sample_flt_logs_nodeb_fqdn: 'Deploy Fleet Management Day-N'!$C$226
Name input_wld_az1_rack5_mgmt_vm_gateway_ip: 'Value Reference Tables - MR'!$P$262
Name wld_az1_rack7_pool_name: 'Value Reference Tables - MR'!$AA$166
Name sample_wld_az1_rack2_edge_overlay_network: Arkham!$B$61
Name input_mgmt_witness_vm_folder: 'Configure Management Domain'!$D$314
Name input_ccm_hcx_service_mesh: 'Cross Cloud Mobility'!$D$39
Name input_wld_az2_vmotion_gateway_ip: 'Configure Workload Domain'!$D$201
Name wld_az1_rack3_host1_hostname: 'Value Reference Tables - MR'!$O$202
Name input_wld_az1_rack8_vmotion_pool_start_ip: 'Additional Racks'!$D$599
Name sample_wld_az1_rack5_host3_mgmt_ip: 'Additional Racks'!$C$295
Name nsxt_gm_root_password: 'Value Reference Tables'!$L$21
Name input_ca_country: 'Configure Management Domain'!$D$61
Name wld_az1_rack8_host7_mgmt_ip: 'Value Reference Tables - MR'!$AD$189
Name mgmt_vrms_site_name: 'Value Reference Tables'!$U$68
Name sample_wld_vrms_mgmt_ip: 'Dumping Ground'!$F$10
Name sample_mgmt_srm_recovery_sddc_manager_domain: 'Dumping Ground'!$C$58
Name input_wld_az1_rack5_host_overlay_vlan: 'Additional Racks'!$D$370
Name sample_wld_rwr_recovery_site_nsx_fqdn: 'On-Premises Ransomware Recovery'!$C$118
Name input_wld_az1_rack6_secondary_storage_pool_start_ip: 'Dumping Ground'!$D$545
Name wld_az1_rack3_rtep_overlay_cidr: 'Value Reference Tables - MR'!$O$33
Name wld_az1_en1_mgmt_ip: Arkham!$R$19
Name input_mgmt_avilb_mgrb_ip: 'Configure Management Domain'!$D$214
Name input_cluster_esx_root_username: 'Deploy Cluster'!$D$104
Name input_wld_az2_storage_cluster_mask: 'Configure Workload Domain'!$D$224
Name input_mgmt_az2_host1_sddc_id: 'Configure Management Domain'!$D$345
Name input_wld_az2_vmotion_pool_end_ip: 'Configure Workload Domain'!$D$203
Name flt_custom_network_chosen: 'Deploy Fleet Management Day-N'!$B$7
Name mgmt_srm_days: 'Value Reference Tables'!$U$83
Name mgmt_cl01_vds02_lacp_mode_chosen: 'Deploy Management Domain'!$L$203
Name input_ccm_aws_management_subnet: 'Cross Cloud Mobility'!$D$26
Name ca_administrator_username: 'Value Reference Tables'!$L$8
Name sample_wld_witness_cluster: 'Configure Workload Domain'!$C$268
Name input_wld_az1_rack8_host16_fqdn: 'Additional Racks'!$D$627
Name sample_wld_az1_principal_storage_mtu: 'Deploy Workload Domain'!$C$94
Name input_wld_az1_rack4_vmotion_pool_end_ip: 'Additional Racks'!$D$228
Name sample_mgmt_az2_vsan_cidr: 'Management Domain As Built'!$C$80
Name sizing_w24_nsxt_gm_appliance_size: 'Management Domain Sizing'!$M$59
Name wld_az1_rack3_rtep_ip_pool_name: 'Value Reference Tables - MR'!$O$173
Name wld_az2_host12_mgmt_ip: 'Value Reference Tables - MR'!$I$434
Name sample_wld_tier0_name: 'Configure Workload Domain'!$C$96

Sheet Prerequisite Checklist
B2: Prerequisite Checklist
B3: The following pre-requisites need to be completed before proceeding with deployments
B6: Hardware (Management Domain)
B7: Server Component | C7: Minimum Requirements | D7: Notes
B8: Server Type | C8: Two Supported Servers - Simple (Single-Node) Deployment or Four Supported Servers - High Availability (Three-Node) Deployment | D8: Refer to the VMware Compatibility Guide at https://compatibilityguide.broadcom.com/ for supported configurations. Note that VMware Cloud Foundation supports three node vSAN clusters in Workload Domains. VMware recommends a minimum of four nodes for production.
B9: CPU | C9: Supported Configurations | D9: None
B10: Memory | C10: Supported Configurations | D10: Rainpole example suggests - 1TB per host based on 4 hosts with ability to tolerate failure of a single host. Use Management Domain Sizing for sizing based on your chosen options.
B11: Storage (Boot) | C11: Supported configurations | D11: SD-Cards are considered legacy and not recommended.
B12: Storage VSAN-OSA (Cache) | C12: Supported Configurations | D12: Rainpole example suggests - 1.2TB of Raw Capacity for the Caching Tier (All-Flash) per host. - Two disk groups, 600GB cache per disk group. Ensure no existing partitions exist on disks intended for use See Designing and Sizing a vSAN Cluster from the VMware vSAN documentation for guidelines about cache sizing. Use Management Domain Sizing for sizing based on your chosen options.
B13: Storage vSAN-OSA (Capacity) | C13: Supported Configurations | D13: Rainpole example suggests - 12.5TB of Raw Capacity for the Capacity Tier (All-Flash) per host. - Two disk groups, 6.25TB per disk group Ensure no existing partitions exist on disks intended for use Use Management Domain Sizing for sizing based on your chosen options.
B14: Storage vSAN-ESA | C14: Supported Configurations | D14: Rainpole example suggests - 12.5TB of Raw Capacity for the Capacity Tier (All-Flash) per host. - 4 x 3.2TB NVME SSD Drives per node. Ensure no existing partitions exist on disks intended for use Use Management Domain Sizing for sizing based on your chosen options.
B15: Storage NFS | C15: Supported Configurations | D15: Use Management Domain Sizing for sizing based on your chosen options.
B16: Storage FC | C16: Supported Configurations | D16: Use Management Domain Sizing for sizing based on your chosen options.
B17: NICs per server | C17: - One 10 GbE NICs - One 1 GbE BMC NIC | D17: Single NIC is supported with API Only 25GbE NICs are recommended for vSAN ESA
B19: Hardware (Workload Domain)
B20: Server Component | C20: Minimum Requirements | D20: Notes
B21: Type | C21: Three Supported Servers | D21: Refer to the VMware Compatibility Guide at https://www.vmware.com/resources/compatibility/search.php for supported configurations. Note that VMware Cloud Foundation supports three node vSAN clusters in Workload Domains. VMware recommends a minimum of four nodes for production. Ensure no existing partitions exist on disks intended for use
B22: CPU | C22: Supported configurations
B23: Memory | C23: Supported configurations
B24: Storage (Boot) | C24: Supported configurations
B25: Storage vSAN-OSA (Cache) | C25: Supported configurations
B26: Storage vSAN-OSA(Capacity) | C26: Supported configurations
B27: Storage vSAN-ESA | C27: Supported configurations
B28: Storage NFS | C28: Supported configurations
B29: Storage FC | C29: Supported configurations
B30: NICs per server | C30: - One 10 GbE NICs - One 1 GbE BMC NIC | D30: Single NIC is supported with API Only VI Workload Domain: Supports a maximum of 64 x pNICs per host 25GbE NICs are recommended for vSAN ESA
B32: Network Requirements
B33: Configuration | C33: Feature | D33: Notes
B34: Physical Network | C34: Jumbo frames | D34: Required for the following traffic types: - vSAN - vSphere vMotion - ESX Host Overlay - NSX Edge Overlay - NFS
C35: BGP adjacency and BGP autonomous system (AS) numbers | D35: Required for Dynamic routing in the SDDC
C36: Teaming Configurations | D36: Use teaming options within vSphere Distributed Switch to provide load-balancing and failover.
C37: Multi-path routing | D37: Verfiy that Equal-cost multi-path routing (ECMP) is supported on interfaces between NSX Edge uplinks and Top-of Rack Switchs (ToRs)
C38: Stretched Network Requirements (Multiple Availability Zone Environments Only) | D38: Verify that routing is in place between ESXI Management IP subnets of Availability Zone 1 (AZ1) and Availability Zone 2 (AZ2). Verify that the following networks from AZ1 are are stretched across the two availability zones. - VM Management network - Uplink01 (If NSX Centralized Connectivity is enabled for Management Domain, or Centralized Connectivity is enabled for Workload Domain) - Uplink02 (If NSX Centralized Connectivity is enabled for Management Domain, or Centralized Connectivity is enabled for Workload Domain) - Edge Overlay (If NSX Centralized Connectivity is enabled for Management Domain, or Centralized Connectivity is enabled for Workload Domain)
B40: VMware Software, Scripts, and Tools
B41: Software | C41: Download Location | D41: Download | E41: Notes
B42: VMware Cloud Foundation Installer | C42: support.broadcom.com | D42: VCF-SDDC-Manager-Appliance-9.0.x.0.xxxxxxxx
B43: Certificate generation utility for VMware Validated Solutions | C43: VMware Knowledge Base article 85527 | D43: CertGenVVS | E43: Use this tool to generate Certificate Signing Request (CSR), OpenSSL CA-signed certificates, and Microsoft CA-signed certificates for all VMware products that are included in the VMware Validated Design. In the context of VMware Validated Solutions, use the CertGenVVS tool to save time in creating signed certificates.
B44: vSAN Witness Appliance | C44: support.broadcom.com | D44: VMware-VirtualSAN-Witness-x.x.x-xxxxxxxx.ova | E44: You use this when deploying a witness appliance to a different fault domain when adding secodary availability zones.
B46: Third Party Software
B47: Software | C47: Vendor | D47: Product / Version | E47: Notes
...

Sheet VCF & VVF Planning
B2: VMware Cloud Foundation and VMware vSphere Foundation Planning
B3: Use this page to select your options for a VMware Cloud Foundation Deployment | M3: =pnp_version_number -> v1.9.0.007
B6: VMware Values
B7: At VMware we value inclusion. To foster this principle within our customer, partner, and internal community, we are replacing some of the terminology in our content. We have updated this document to remove instances of non-inclusive language.
J9: Version
J10: VMware Cloud Foundation
J11: =IF(vcf_version_chosen="No Version Selected","Select Version",vcf_version_chosen) -> 9.0.2.0
J14: Deployment Type
J15: Select Option | K15: Feature | L15: Final Result | M15: Information
J16: 9.0.2.0 | K16: =CONCATENATE(mgmt_domain_deployment_type_chosen," Deployment Version") -> VMware Cloud Foundation Deployment Version | L16: =IF(vcf_version_chosen="No Version Selected","Excluded","Included") -> Included | M16: =IF(vcf_version_result="Excluded",CONCATENATE("Cause: ",mgmt_domain_deployment_type_chosen, " Deployment Version is not selected"),CONCATENATE(mgmt_domain_deployment_type_chosen," Version ",vcf_version," selected")) -> VMware Cloud Foundation Version 9.0.2.0 selected
J17: VMware Cloud Foundation | K17: Deployment Specification | L17: =IF(vcf_version_chosen="No Version Selected","Excluded","Included") -> Included | M17: =IF(vcf_version_result="Excluded",CONCATENATE("Cause: ",mgmt_domain_deployment_type_chosen, " Deployment Version is not selected"),IF(mgmt_domain_deployment_type_chosen="VMware Cloud Foundation","VMware Cloud Foundation Private Cloud will be deployed","VMware vSphere Foundation will be deployed")) -> VMware Cloud Foundation Private Cloud will be deployed
J18: Additional Instance | K18: Instance to perform operation on | L18: =IF(vcf_version_chosen="No Version Selected","Excluded",IF(mgmt_domain_deployment_type_chosen="VMware vSphere Foundation","Excluded",IF(mgmt_domain_chosen="Deploy a new VCF fleet","Included","Included"))) -> Included | M18: =IF(vcf_version_result="Excluded",CONCATENATE("Cause: ",mgmt_domain_deployment_type_chosen, " Deployment Version is not selected"),IF(mgmt_domain_deployment_type_chosen="VMware vSphere Foundation","Option not required for deployment specification type",IF(mgmt_domain_chosen="First Instance","Operation will be performed on the First VCF Instance","Operation will be performed on an additional VCF Instance"))) -> Operation will be performed on an additional VCF Instance
J19: Deploy a VCF Instance in an existing VCF fleet | K19: Operation to be performed | L19: =IF(vcf_version_chosen="No Version Selected","Excluded", IF(AND(mgmt_domain_deployment_type_chosen="VMware vSphere Foundation",vcf_granular_option_chosen="Create VI Workload Domain"),"Excluded", IF(AND(mgmt_domain_deployment_type_chosen="VMware vSphere Foundation",vcf_granular_option_chosen="Create Cluster"),"Excluded", IF(AND(mgmt_domain_deployment_type_chosen="VMware Cloud Foundation",vcf_granular_option_chosen="VMware vSphere Foundation Deployment"),"Excluded", IF(vcf_granular_option_chosen="None Chosen","Excluded","Included"))))) -> Included | M19: =IF(vcf_version_result="Excluded",CONCATENATE("Cause: ",mgmt_domain_deployment_type_chosen," Deployment Version is not selected"), IF(AND(mgmt_domain_deployment_type_chosen="VMware vSphere Foundation",vcf_granular_option_chosen="Create VI Workload Domain"),"Option not supported for deployment specification type", IF(AND(mgmt_domain_deployment_type_chosen="VMware vSphere Foundation",vcf_granular_option_chosen="Create Cluster"),"Option not supported for deployment specification type", IF(AND(mgmt_domain_deployment_type_chosen="VMware Cloud Foundation",vcf_granular_option_chosen="VMware vSphere Foundation Deployment"),"Option not supported for deployment specification type", IF(vcf_granular_option_chosen="None Chosen","No Deployment Type Chosen",IF(vcf_granular_option_chosen="Deploy a new VCF fleet","VMware Cloud Foundation Installer will deploy a new VCF fleet", IF(vcf_granular_option_chosen="Deploy a VCF Instance in an existing VCF fleet","VMware Cloud Foundation Installer will deploy a new VCF Instance in an existing VCF fleet", IF(vcf_granular_option_chosen="Create Cluster","A cluster will be added to an existing Workload Domain", IF(vcf_granular_option_chosen="Create VI Workload Domain","A VI Workload Domain will be added on an exsiting VCF Instance", IF(vcf_granular_option_chosen="VMware vSphere Foundation Deployment","Deploy a new VMware vSphere Foundation Cluster","")))))))))) -> VMware Cloud Foundation Installer will deploy a new VCF Instance in an existing VCF fleet

Sheet Management Domain Sizing
B2: VMware Cloud Foundation Management Domain Sizing Inputs
B6: Management Domain Assumptions | G6: Management Domain Virtual Machine Requirement Summary | O6: Host Requirement Summary | U6: Notes
B7: Component | E7: Value | G7: Component | J7: Nodes | K7: vCPU | L7: RAM (GB) | M7: Disk (GB) | O7: Management Hosts | R7: Number of Hosts | U7: General Guidance • Configure the Assumptions and Host parameters according to your preference. Set VCF Operations and Automation Deployment models and Sizes according to your requirements. Include Identity Broker if you plan to configure VCF Authentication using the Identity Broker appliance. • The over-subscription ratio maximums of 2:1 are designed to ensure a performant management domain for most deployments. Regardless of the ratios you choose, you should monitor the platform continuously and add hardware if consistent performance bottlenecks are observed • Appliance sizes are listed per appliance. Totals are calculated in the requirements summary table • vSAN and Non-vSAN storage Space capacity requirements are both listed as VCF 9.0 Supports Non-vSAN Storage in the Management Domain vSphere and NSX Sizing • As each workload domain requires additional vSphere and, optionally, NSX components to be deployed, this tab allows you to correctly calculate the requirements for your management domain by selecting the intended number and profile of workload domains you plan to deploy. • This workbook allows for gathering inputs for the management domain and the first workload domain only (w01). To gather inputs for subsequent workload domains (w02 through w24), you should use separate copies of this file for each domain. • The management domain is mandatory and cannot be deselected. Its NSX Manager instance is required and dedicated. • The NSX instance for the first workload domain is mandatory, subsequent workload domains may share this instance or deploy a dedicated instance. • A maximum of four NSX Local Manager instances may be federated by a single NSX Global Manager instance. This includes inter-region and intra-region NSX Local Manager instances. Factor in this maximum when deciding whether to include Global Manager resources for a new workload domain. VCF Operations and Automation Sizing • If VCF Operations is already existing, then sizing input is not required for VCF Operations and VCF Automation • Appliance Deployment Model sets the HA deployment model for VCF Operations and VCF Automation Security Service Platform: SSPI = Security Services Platform Installer; SSP = Security Services Platform Medium = 1 SSPI + 3 SSP Controller Nodes + 5 SSP Worker Nodes; Large = 1 SSPI + 3 SSP Controller Nodes + 8 SSP Worker Node; X-Large = 1 SSPI + 3 SSP Controller Nodes + 10 SSP Worker Nodes
B8: Host and Operations Reserve (%) | E8: 30 | G8: SDDC Manager | J8: 1 | K8: =sizing_sddc_manager_cpu -> 4 | L8: =sizing_sddc_manager_ram -> 16 | M8: =sizing_sddc_manager_disk -> 914 | O8: Hosts count based on User Specification | R8: {=IF(OR(H32="Mandatory - HA Cluster",sizing_vcfops_deployment_model_chosen="Deploy HA",sizing_vcfvidb_chosen="Deploy HA"),MAX(4,(ROUNDUP(((SUM(K8:K27)/sizing_cpu_oversubscription)/sizing_mgmt_cluster_host_core_count),0)),((ROUNDUP((SUM(L8:L27/sizing_ram_oversubscription)/sizing_mgmt_cluster_host_ram_count),0))+1)), IF(OR(sizing_storage_type="vSAN-ESA",sizing_storage_type="vSAN-OSA"),MAX(3,(ROUNDUP(((SUM(K8:K27)/sizing_cpu_oversubscription)/sizing_mgmt_cluster_host_core_count),0)),((ROUNDUP((SUM(L8:L27/sizing_ram_oversubscription)/sizing_mgmt_cluster_host_ram_count),0))+1)),MAX(2,(ROUNDUP(((SUM(K8:K27)/sizing_cpu_oversubscription)/sizing_mgmt_cluster_host_core_count),0)),((ROUNDUP((SUM(L8:L27/sizing_ram_oversubscription)/sizing_mgmt_cluster_host_ram_count),0))+1))))} -> 4
B9: Storage Estimated Growth (%) | E9: 10 | G9: Management Domain vSphere Cluster Services | J9: 2 | K9: 2 | L9: 1 | M9: 0 | O9: CPU usage Per Host (based on N-1 hosts) | R9: =CONCATENATE(ROUNDUP(SUM(K8:K27)/(calculated_mgmt_host_count-1)/sizing_cpu_oversubscription,0)," CPUs") -> 10 CPUs
G10: Management Domain vCenter Server | J10: 1 | K10: =IF(sizing_m01_included="Included",VLOOKUP(D32,table_vcenter_appliance_cpu,2,FALSE),0) -> 8 | L10: =IF(sizing_m01_included="Included",VLOOKUP(D32,table_vcenter_appliance_ram,2,FALSE),0) -> 30 | M10: =IF(sizing_m01_included="Included",VLOOKUP(CONCATENATE(D32,F32),table_vcenter_disk_gb,2,FALSE),0) -> 908 | O10: RAM usage Per Host (based on N-1 hosts) | R10: =CONCATENATE(ROUNDUP(SUM(L8:L27)/(calculated_mgmt_host_count-1)/sizing_ram_oversubscription,0)," GB RAM") -> 69 GB RAM
B11: Management Domain Host Parameters | G11: Management Domain NSX Managers (Local Global) | J11: =SUM(IF(H32="Mandatory - Single Node",1,3),IF(sizing_m01_nsxt_gm_appliance_size<>"Excluded",3,0)) -> 6 | K11: =SUM(PRODUCT(VLOOKUP(sizing_m01_nsxt_appliance_size,table_nsxt_manager_cpu,2,FALSE),IF(H32="Mandatory - HA Cluster",3,1)),(PRODUCT(IF(sizing_m01_nsxt_gm_appliance_size<>"Excluded",VLOOKUP(sizing_m01_nsxt_gm_appliance_size,table_nsxt_manager_cpu,2,FALSE),0),3))) -> 36 | L11: =SUM(PRODUCT(VLOOKUP(sizing_m01_nsxt_appliance_size,table_nsxt_manager_ram,2,FALSE),IF(H32="Mandatory - HA Cluster",3,1)),(PRODUCT(IF(sizing_m01_nsxt_gm_appliance_size<>"Excluded",VLOOKUP(sizing_m01_nsxt_gm_appliance_size,table_nsxt_manager_ram,2,FALSE),0),3))) -> 144 | M11: =SUM(PRODUCT(VLOOKUP(sizing_m01_nsxt_appliance_size,table_nsxt_manager_disk_gb,2,FALSE),IF(H32="Mandatory - HA Cluster",3,1)),(PRODUCT(IF(sizing_m01_nsxt_gm_appliance_size<>"Excluded",VLOOKUP(sizing_m01_nsxt_gm_appliance_size,table_nsxt_manager_disk_gb,2,FALSE),0),3))) -> 1800
B12: Attribute | E12: Value | G12: Management Domain NSX Edges | J12: =IF(sizing_m01_nsxt_edge_size<>"Excluded",2,0) -> 2 | K12: =PRODUCT(IF(AND(sizing_m01_nsxt_edge_size<>"Excluded",sizing_m01_included="Included"),VLOOKUP(sizing_m01_nsxt_edge_size,table_nsxt_edge_cpu,2,FALSE),0),J12) -> 8 | L12: =PRODUCT(IF(AND(sizing_m01_nsxt_edge_size<>"Excluded",sizing_m01_included="Included"),VLOOKUP(sizing_m01_nsxt_edge_size,table_nsxt_edge_ram,2,FALSE),0),2) -> 16 | M12: =PRODUCT(IF(AND(sizing_m01_nsxt_edge_size<>"Excluded",sizing_m01_included="Included"),VLOOKUP(sizing_m01_nsxt_edge_size,table_nsxt_edge_disk_gb,2,FALSE),0),J12) -> 400 | O12: vSAN Storage Requirements if used as Primary Storage
B13: CPU Cores | E13: 64 | G13: Management Domain AVI Load Balancer | J13: =IF(sizing_mgmt_avi_lb_appliance_size="Excluded",0,3) -> 0 | K13: =IF(sizing_mgmt_avi_lb_appliance_size="Excluded",0,PRODUCT(J13,IF(AND(sizing_m01_included="Included",sizing_mgmt_avi_lb_appliance_size<>"Excluded"),VLOOKUP(sizing_mgmt_avi_lb_appliance_size,table_avi_lb_cpu,2,FALSE),0))) -> 0 | L13: =IF(sizing_mgmt_avi_lb_appliance_size="Excluded",0,PRODUCT(J13,IF(AND(sizing_m01_included="Included",sizing_mgmt_avi_lb_appliance_size<>"Excluded"),VLOOKUP(sizing_mgmt_avi_lb_appliance_size,table_avi_lb_ram,2,FALSE),0))) -> 0 | M13: =IF(sizing_mgmt_avi_lb_appliance_size="Excluded",0,PRODUCT(J13,IF(AND(sizing_m01_included="Included",sizing_mgmt_avi_lb_appliance_size<>"Excluded"),VLOOKUP(sizing_mgmt_avi_lb_appliance_size,table_avi_lb_disk,2,FALSE),0))) -> 0 | O13: vSAN Storage Type | R13: NFS
B14: RAM Count (GB) | E14: 384 | G14: Management Workload Security Services Platform | J14: =IF(sizing_m01_ssp_chosen="Medium",9,IF(sizing_m01_ssp_chosen="Large",12,IF(sizing_m01_ssp_chosen="X-Large",14,0))) -> 0 | K14: =IF(sizing_m01_ssp_chosen<>"Excluded",VLOOKUP(sizing_m01_ssp_chosen,table_ssp_cpu,2,FALSE),0) -> 0 | L14: =IF(sizing_m01_ssp_chosen<>"Excluded",VLOOKUP(sizing_m01_ssp_chosen,table_ssp_ram,2,FALSE),0) -> 0 | M14: =IF(sizing_m01_ssp_chosen<>"Excluded",VLOOKUP(sizing_m01_ssp_chosen,table_ssp_disk,2,FALSE),0) -> 0 | O14: Component | R14: GB
B15: CPU Oversubscription (X:1) | E15: 2 | G15: Workload Domain vCenter Servers | J15: =COUNTIF(C36:C59,"Included") -> 0 | K15: =(SUM(IF(sizing_w01_chosen="Included",VLOOKUP(sizing_w01_vcenter_appliance_size,table_vcenter_appliance_cpu,2,FALSE)), IF(sizing_w02_chosen="Included",VLOOKUP(sizing_w02_vcenter_appliance_size,table_vcenter_appliance_cpu,2,FALSE)), IF(sizing_w03_chosen="Included",VLOOKUP(sizing_w03_vcenter_appliance_size,table_vcenter_appliance_cpu,2,FALSE)), IF(sizing_w04_chosen="Included",VLOOKUP(sizing_w04_vcenter_appliance_size,table_vcenter_appliance_cpu,2,FALSE)), IF(sizing_w05_chosen="Included",VLOOKUP(sizing_w05_vcenter_appliance_size,table_vcenter_appliance_cpu,2,FALSE)), IF(sizing_w06_chosen="Included",VLOOKUP(sizing_w06_vcenter_appliance_size,table_vcenter_appliance_cpu,2,FALSE)), IF(sizing_w07_chosen="Included",VLOOKUP(sizing_w07_vcenter_appliance_size,table_vcenter_appliance_cpu,2,FALSE)), IF(sizing_w08_chosen="Included",VLOOKUP(sizing_w08_vcenter_appliance_size,table_vcenter_appliance_cpu,2,FALSE)), IF(sizing_w09_chosen="Included",VLOOKUP(sizing_w09_vcenter_appliance_size,table_vcenter_appliance_cpu,2,FALSE)), IF(sizing_w10_chosen="Included",VLOOKUP(sizing_w10_vcenter_appliance_size,table_vcenter_appliance_cpu,2,FALSE)), IF(sizing_w11_chosen="Included",VLOOKUP(sizing_w11_vcenter_appliance_size,table_vcenter_appliance_cpu,2,FALSE)), IF(sizing_w12_chosen="Included",VLOOKUP(sizing_w12_vcenter_appliance_size,table_vcenter_appliance_cpu,2,FALSE)), IF(sizing_w13_chosen="Included",VLOOKUP(sizing_w13_vcenter_appliance_size,table_vcenter_appliance_cpu,2,FALSE)), IF(sizing_w14_chosen="Included",VLOOKUP(sizing_w14_vcenter_appliance_size,table_vcenter_appliance_cpu,2,FALSE)), IF(sizing_w15_chosen="Included",VLOOKUP(sizing_w15_vcenter_appliance_size,table_vcenter_appliance_cpu,2,FALSE)), IF(sizing_w16_chosen="Included",VLOOKUP(sizing_w16_vcenter_appliance_size,table_vcenter_appliance_cpu,2,FALSE)), IF(sizing_w17_chosen="Included",VLOOKUP(sizing_w17_vcenter_appliance_size,table_vcenter_appliance_cpu,2,FALSE)), IF(sizing_w18_chosen="Included",VLOOKUP(sizing_w18_vcenter_appliance_size,table_vcenter_appliance_cpu,2,FALSE)), IF(sizing_w19_chosen="Included",VLOOKUP(sizing_w19_vcenter_appliance_size,table_vcenter_appliance_cpu,2,FALSE)), IF(sizing_w20_chosen="Included",VLOOKUP(sizing_w20_vcenter_appliance_size,table_vcenter_appliance_cpu,2,FALSE)), IF(sizing_w21_chosen="Included",VLOOKUP(sizing_w21_vcenter_appliance_size,table_vcenter_appliance_cpu,2,FALSE)), IF(sizing_w22_chosen="Included",VLOOKUP(sizing_w22_vcenter_appliance_size,table_vcenter_appliance_cpu,2,FALSE)), IF(sizing_w23_chosen="Included",VLOOKUP(sizing_w23_vcenter_appliance_size,table_vcenter_appliance_cpu,2,FALSE)), IF(sizing_w24_chosen="Included",VLOOKUP(sizing_w24_vcenter_appliance_size,table_vcenter_appliance_cpu,2,FALSE)), )) -> 0 | L15: =SUM(IF(sizing_w01_chosen="Included",VLOOKUP(sizing_w01_vcenter_appliance_size,table_vcenter_appliance_ram,2,FALSE)), IF(sizing_w02_chosen="Included",VLOOKUP(sizing_w02_vcenter_appliance_size,table_vcenter_appliance_ram,2,FALSE)), IF(sizing_w03_chosen="Included",VLOOKUP(sizing_w03_vcenter_appliance_size,table_vcenter_appliance_ram,2,FALSE)), IF(sizing_w04_chosen="Included",VLOOKUP(sizing_w04_vcenter_appliance_size,table_vcenter_appliance_ram,2,FALSE)), IF(sizing_w05_chosen="Included",VLOOKUP(sizing_w05_vcenter_appliance_size,table_vcenter_appliance_ram,2,FALSE)), IF(sizing_w06_chosen="Included",VLOOKUP(sizing_w06_vcenter_appliance_size,table_vcenter_appliance_ram,2,FALSE)), IF(sizing_w07_chosen="Included",VLOOKUP(sizing_w07_vcenter_appliance_size,table_vcenter_appliance_ram,2,FALSE)), IF(sizing_w08_chosen="Included",VLOOKUP(sizing_w08_vcenter_appliance_size,table_vcenter_appliance_ram,2,FALSE)), IF(sizing_w09_chosen="Included",VLOOKUP(sizing_w09_vcenter_appliance_size,table_vcenter_appliance_ram,2,FALSE)), IF(sizing_w10_chosen="Included",VLOOKUP(sizing_w10_vcenter_appliance_size,table_vcenter_appliance_ram,2,FALSE)), IF(sizing_w11_chosen="Included",VLOOKUP(sizing_w11_vcenter_appliance_size,table_vcenter_appliance_ram,2,FALSE)), IF(sizing_w12_chosen="Included",VLOOKUP(sizing_w12_vcenter_appliance_size,table_vcenter_appliance_ram,2,FALSE)), IF(sizing_w13_chosen="Included",VLOOKUP(sizing_w13_vcenter_appliance_size,table_vcenter_appliance_ram,2,FALSE)), IF(sizing_w14_chosen="Included",VLOOKUP(sizing_w14_vcenter_appliance_size,table_vcenter_appliance_ram,2,FALSE)), IF(sizing_w15_chosen="Included",VLOOKUP(sizing_w15_vcenter_appliance_size,table_vcenter_appliance_ram,2,FALSE)), IF(sizing_w16_chosen="Included",VLOOKUP(sizing_w16_vcenter_appliance_size,table_vcenter_appliance_ram,2,FALSE)), IF(sizing_w17_chosen="Included",VLOOKUP(sizing_w17_vcenter_appliance_size,table_vcenter_appliance_ram,2,FALSE)), IF(sizing_w18_chosen="Included",VLOOKUP(sizing_w18_vcenter_appliance_size,table_vcenter_appliance_ram,2,FALSE)), IF(sizing_w19_chosen="Included",VLOOKUP(sizing_w19_vcenter_appliance_size,table_vcenter_appliance_ram,2,FALSE)), IF(sizing_w20_chosen="Included",VLOOKUP(sizing_w20_vcenter_appliance_size,table_vcenter_appliance_ram,2,FALSE)), IF(sizing_w21_chosen="Included",VLOOKUP(sizing_w21_vcenter_appliance_size,table_vcenter_appliance_ram,2,FALSE)), IF(sizing_w22_chosen="Included",VLOOKUP(sizing_w22_vcenter_appliance_size,table_vcenter_appliance_ram,2,FALSE)), IF(sizing_w23_chosen="Included",VLOOKUP(sizing_w23_vcenter_appliance_size,table_vcenter_appliance_ram,2,FALSE)), IF(sizing_w24_chosen="Included",VLOOKUP(sizing_w24_vcenter_appliance_size,table_vcenter_appliance_ram,2,FALSE)), ) -> 0 | M15: =SUM((IF(sizing_w01_chosen="Included",VLOOKUP(CONCATENATE(sizing_w01_vcenter_appliance_size,sizing_w01_vcenter_storage_size),table_vcenter_disk_gb,2,FALSE),0)), IF(sizing_w02_chosen="Included",VLOOKUP(CONCATENATE(sizing_w02_vcenter_appliance_size,sizing_w02_vcenter_storage_size),table_vcenter_disk_gb,2,FALSE),0), IF(sizing_w03_chosen="Included",VLOOKUP(CONCATENATE(sizing_w03_vcenter_appliance_size,sizing_w03_vcenter_storage_size),table_vcenter_disk_gb,2,FALSE),0), IF(sizing_w04_chosen="Included",VLOOKUP(CONCATENATE(sizing_w04_vcenter_appliance_size,sizing_w04_vcenter_storage_size),table_vcenter_disk_gb,2,FALSE),0), IF(sizing_w05_chosen="Included",VLOOKUP(CONCATENATE(sizing_w05_vcenter_appliance_size,sizing_w05_vcenter_storage_size),table_vcenter_disk_gb,2,FALSE),0), IF(sizing_w06_chosen="Included",VLOOKUP(CONCATENATE(sizing_w06_vcenter_appliance_size,sizing_w06_vcenter_storage_size),table_vcenter_disk_gb,2,FALSE),0), IF(sizing_w07_chosen="Included",VLOOKUP(CONCATENATE(sizing_w07_vcenter_appliance_size,sizing_w07_vcenter_storage_size),table_vcenter_disk_gb,2,FALSE),0), IF(sizing_w08_chosen="Included",VLOOKUP(CONCATENATE(sizing_w08_vcenter_appliance_size,sizing_w08_vcenter_storage_size),table_vcenter_disk_gb,2,FALSE),0), IF(sizing_w09_chosen="Included",VLOOKUP(CONCATENATE(sizing_w09_vcenter_appliance_size,sizing_w09_vcenter_storage_size),table_vcenter_disk_gb,2,FALSE),0), IF(sizing_w10_chosen="Included",VLOOKUP(CONCATENATE(sizing_w10_vcenter_appliance_size,sizing_w10_vcenter_storage_size),table_vcenter_disk_gb,2,FALSE),0), IF(sizing_w11_chosen="Included",VLOOKUP(CONCATENATE(sizing_w11_vcenter_appliance_size,sizing_w11_vcenter_storage_size),table_vcenter_disk_gb,2,FALSE),0), IF(sizing_w12_chosen="Included",VLOOKUP(CONCATENATE(sizing_w12_vcenter_appliance_size,sizing_w12_vcenter_storage_size),table_vcenter_disk_gb,2,FALSE),0), IF(sizing_w13_chosen="Included",VLOOKUP(CONCATENATE(sizing_w13_vcenter_appliance_size,sizing_w13_vcenter_storage_size),table_vcenter_disk_gb,2,FALSE),0), IF(sizing_w14_chosen="Included",VLOOKUP(CONCATENATE(sizing_w14_vcenter_appliance_size,sizing_w14_vcenter_storage_size),table_vcenter_disk_gb,2,FALSE),0), IF(sizing_w15_chosen="Included",VLOOKUP(CONCATENATE(sizing_w15_vcenter_appliance_size,sizing_w15_vcenter_storage_size),table_vcenter_disk_gb,2,FALSE),0), IF(sizing_w16_chosen="Included",VLOOKUP(CONCATENATE(sizing_w16_vcenter_appliance_size,sizing_w16_vcenter_storage_size),table_vcenter_disk_gb,2,FALSE),0), IF(sizing_w17_chosen="Included",VLOOKUP(CONCATENATE(sizing_w17_vcenter_appliance_size,sizing_w17_vcenter_storage_size),table_vcenter_disk_gb,2,FALSE),0), IF(sizing_w18_chosen="Included",VLOOKUP(CONCATENATE(sizing_w18_vcenter_appliance_size,sizing_w18_vcenter_storage_size),table_vcenter_disk_gb,2,FALSE),0), IF(sizing_w19_chosen="Included",VLOOKUP(CONCATENATE(sizing_w19_vcenter_appliance_size,sizing_w19_vcenter_storage_size),table_vcenter_disk_gb,2,FALSE),0), IF(sizing_w20_chosen="Included",VLOOKUP(CONCATENATE(sizing_w20_vcenter_appliance_size,sizing_w20_vcenter_storage_size),table_vcenter_disk_gb,2,FALSE),0), IF(sizing_w21_chosen="Included",VLOOKUP(CONCATENATE(sizing_w21_vcenter_appliance_size,sizing_w21_vcenter_storage_size),table_vcenter_disk_gb,2,FALSE),0), IF(sizing_w22_chosen="Included",VLOOKUP(CONCATENATE(sizing_w22_vcenter_appliance_size,sizing_w22_vcenter_storage_size),table_vcenter_disk_gb,2,FALSE),0), IF(sizing_w23_chosen="Included",VLOOKUP(CONCATENATE(sizing_w23_vcenter_appliance_size,sizing_w23_vcenter_storage_size),table_vcenter_disk_gb,2,FALSE),0), IF(sizing_w24_chosen="Included",VLOOKUP(CONCATENATE(sizing_w24_vcenter_appliance_size,sizing_w24_vcenter_storage_size),table_vcenter_disk_gb,2,FALSE),0), ) -> 0 | O15: Virtual Machine Capacity Requirements | R15: =(SUM(M8:M27)) -> 4022
B16: Memory Oversubscription (X:1) | E16: 1 | G16: Workload Domain NSX Managers (Local Global) | J16: =SUM( (IF(AND(sizing_w01_chosen="Included",sizing_w01_nsxt_model<>"Shared"),IF(sizing_w01_nsxt_model="Mandatory - HA Cluster",3,1),0)), (IF(AND(sizing_w02_chosen="Included",sizing_w02_nsxt_model<>"Shared"),IF(sizing_w02_nsxt_model="Dedicated - HA Cluster",3,1),0)), (IF(AND(sizing_w03_chosen="Included",sizing_w03_nsxt_model<>"Shared"),IF(sizing_w03_nsxt_model="Dedicated - HA Cluster",3,1),0)), (IF(AND(sizing_w04_chosen="Included",sizing_w04_nsxt_model<>"Shared"),IF(sizing_w04_nsxt_model="Dedicated - HA Cluster",3,1),0)), (IF(AND(sizing_w05_chosen="Included",sizing_w05_nsxt_model<>"Shared"),IF(sizing_w05_nsxt_model="Dedicated - HA Cluster",3,1),0)), (IF(AND(sizing_w06_chosen="Included",sizing_w06_nsxt_model<>"Shared"),IF(sizing_w06_nsxt_model="Dedicated - HA Cluster",3,1),0)), (IF(AND(sizing_w07_chosen="Included",sizing_w07_nsxt_model<>"Shared"),IF(sizing_w07_nsxt_model="Dedicated - HA Cluster",3,1),0)), (IF(AND(sizing_w08_chosen="Included",sizing_w08_nsxt_model<>"Shared"),IF(sizing_w08_nsxt_model="Dedicated - HA Cluster",3,1),0)), (IF(AND(sizing_w09_chosen="Included",sizing_w09_nsxt_model<>"Shared"),IF(sizing_w09_nsxt_model="Dedicated - HA Cluster",3,1),0)),, (IF(AND(sizing_w10_chosen="Included",sizing_w10_nsxt_model<>"Shared"),IF(sizing_w10_nsxt_model="Dedicated - HA Cluster",3,1),0)), (IF(AND(sizing_w11_chosen="Included",sizing_w11_nsxt_model<>"Shared"),IF(sizing_w11_nsxt_model="Dedicated - HA Cluster",3,1),0)), (IF(AND(sizing_w12_chosen="Included",sizing_w12_nsxt_model<>"Shared"),IF(sizing_w12_nsxt_model="Dedicated - HA Cluster",3,1),0)), (IF(AND(sizing_w13_chosen="Included",sizing_w13_nsxt_model<>"Shared"),IF(sizing_w13_nsxt_model="Dedicated - HA Cluster",3,1),0)), (IF(AND(sizing_w14_chosen="Included",sizing_w14_nsxt_model<>"Shared"),IF(sizing_w14_nsxt_model="Dedicated - HA Cluster",3,1),0)), (IF(AND(sizing_w15_chosen="Included",sizing_w15_nsxt_model<>"Shared"),IF(sizing_w15_nsxt_model="Dedicated - HA Cluster",3,1),0)), (IF(AND(sizing_w16_chosen="Included",sizing_w16_nsxt_model<>"Shared"),IF(sizing_w16_nsxt_model="Dedicated - HA Cluster",3,1),0)), (IF(AND(sizing_w17_chosen="Included",sizing_w17_nsxt_model<>"Shared"),IF(sizing_w17_nsxt_model="Dedicated - HA Cluster",3,1),0)), (IF(AND(sizing_w18_chosen="Included",sizing_w18_nsxt_model<>"Shared"),IF(sizing_w18_nsxt_model="Dedicated - HA Cluster",3,1),0)), (IF(AND(sizing_w19_chosen="Included",sizing_w19_nsxt_model<>"Shared"),IF(sizing_w19_nsxt_model="Dedicated - HA Cluster",3,1),0)), (IF(AND(sizing_w20_chosen="Included",sizing_w20_nsxt_model<>"Shared"),IF(sizing_w20_nsxt_model="Dedicated - HA Cluster",3,1),0)), (IF(AND(sizing_w21_chosen="Included",sizing_w21_nsxt_model<>"Shared"),IF(sizing_w21_nsxt_model="Dedicated - HA Cluster",3,1),0)), (IF(AND(sizing_w22_chosen="Included",sizing_w22_nsxt_model<>"Shared"),IF(sizing_w22_nsxt_model="Dedicated - HA Cluster",3,1),0)), (IF(AND(sizing_w23_chosen="Included",sizing_w23_nsxt_model<>"Shared"),IF(sizing_w23_nsxt_model="Dedicated - HA Cluster",3,1),0)), (IF(AND(sizing_w24_chosen="Included",sizing_w24_nsxt_model<>"Shared"),IF(sizing_w24_nsxt_model="Dedicated - HA Cluster",3,1),0)), (IF(AND(sizing_w01_chosen="Included",OR(sizing_w01_gm_chosen="Active GM",sizing_w01_gm_chosen="Standby GM")),3,0)), (IF(AND(sizing_w02_chosen="Included",OR(sizing_w02_gm_chosen="Active GM",sizing_w02_gm_chosen="Standby GM")),3,0)), (IF(AND(sizing_w03_chosen="Included",OR(sizing_w03_gm_chosen="Active GM",sizing_w03_gm_chosen="Standby GM")),3,0)), (IF(AND(sizing_w04_chosen="Included",OR(sizing_w04_gm_chosen="Active GM",sizing_w04_gm_chosen="Standby GM")),3,0)), (IF(AND(sizing_w05_chosen="Included",OR(sizing_w05_gm_chosen="Active GM",sizing_w05_gm_chosen="Standby GM")),3,0)), (IF(AND(sizing_w06_chosen="Included",OR(sizing_w06_gm_chosen="Active GM",sizing_w06_gm_chosen="Standby GM")),3,0)), (IF(AND(sizing_w07_chosen="Included",OR(sizing_w07_gm_chosen="Active GM",sizing_w07_gm_chosen="Standby GM")),3,0)), (IF(AND(sizing_w08_chosen="Included",OR(sizing_w08_gm_chosen="Active GM",sizing_w08_gm_chosen="Standby GM")),3,0)), (IF(AND(sizing_w09_chosen="Included",OR(sizing_w09_gm_chosen="Active GM",sizing_w09_gm_chosen="Standby GM")),3,0)), (IF(AND(sizing_w10_chosen="Included",OR(sizing_w10_gm_chosen="Active GM",sizing_w10_gm_chosen="Standby GM")),3,0)), (IF(AND(sizing_w11_chosen="Included",OR(sizing_w11_gm_chosen="Active GM",sizing_w11_gm_chosen="Standby GM")),3,0)), (IF(AND(sizing_w12_chosen="Included",OR(sizing_w12_gm_chosen="Active GM",sizing_w12_gm_chosen="Standby GM")),3,0)), (IF(AND(sizing_w13_chosen="Included",OR(sizing_w13_gm_chosen="Active GM",sizing_w13_gm_chosen="Standby GM")),3,0)), (IF(AND(sizing_w14_chosen="Included",OR(sizing_w14_gm_chosen="Active GM",sizing_w14_gm_chosen="Standby GM")),3,0)), (IF(AND(sizing_w15_chosen="Included",OR(sizing_w15_gm_chosen="Active GM",sizing_w15_gm_chosen="Standby GM")),3,0)), (IF(AND(sizing_w16_chosen="Included",OR(sizing_w16_gm_chosen="Active GM",sizing_w16_gm_chosen="Standby GM")),3,0)), (IF(AND(sizing_w17_chosen="Included",OR(sizing_w17_gm_chosen="Active GM",sizing_w17_gm_chosen="Standby GM")),3,0)), (IF(AND(sizing_w18_chosen="Included",OR(sizing_w18_gm_chosen="Active GM",sizing_w18_gm_chosen="Standby GM")),3,0)), (IF(AND(sizing_w19_chosen="Included",OR(sizing_w19_gm_chosen="Active GM",sizing_w19_gm_chosen="Standby GM")),3,0)), (IF(AND(sizing_w20_chosen="Included",OR(sizing_w20_gm_chosen="Active GM",sizing_w20_gm_chosen="Standby GM")),3,0)), (IF(AND(sizing_w21_chosen="Included",OR(sizing_w21_gm_chosen="Active GM",sizing_w21_gm_chosen="Standby GM")),3,0)), (IF(AND(sizing_w22_chosen="Included",OR(sizing_w22_gm_chosen="Active GM",sizing_w22_gm_chosen="Standby GM")),3,0)), (IF(AND(sizing_w23_chosen="Included",OR(sizing_w23_gm_chosen="Active GM",sizing_w23_gm_chosen="Standby GM")),3,0)), (IF(AND(sizing_w24_chosen="Included",OR(sizing_w24_gm_chosen="Active GM",sizing_w24_gm_chosen="Standby GM")),3,0))) -> 0 | K16: =SUM( PRODUCT((IF(AND(sizing_w01_chosen="Included",sizing_w01_nsxt_model<>"Shared"),VLOOKUP(sizing_w01_nsxt_appliance_size,table_nsxt_manager_cpu,2,FALSE),0)),IF(sizing_w01_nsxt_model="Mandatory - HA Cluster",3,1)), PRODUCT((IF(AND(sizing_w02_chosen="Included",sizing_w02_nsxt_model<>"Shared"),VLOOKUP(sizing_w02_nsxt_appliance_size,table_nsxt_manager_cpu,2,FALSE),0)),IF(sizing_w02_nsxt_model="Dedicated - HA Cluster",3,1)), PRODUCT((IF(AND(sizing_w03_chosen="Included",sizing_w03_nsxt_model<>"Shared"),VLOOKUP(sizing_w03_nsxt_appliance_size,table_nsxt_manager_cpu,2,FALSE),0)),IF(sizing_w03_nsxt_model="Dedicated - HA Cluster",3,1)), PRODUCT((IF(AND(sizing_w04_chosen="Included",sizing_w04_nsxt_model<>"Shared"),VLOOKUP(sizing_w04_nsxt_appliance_size,table_nsxt_manager_cpu,2,FALSE),0)),IF(sizing_w04_nsxt_model="Dedicated - HA Cluster",3,1)), PRODUCT((IF(AND(sizing_w05_chosen="Included",sizing_w05_nsxt_model<>"Shared"),VLOOKUP(sizing_w05_nsxt_appliance_size,table_nsxt_manager_cpu,2,FALSE),0)),IF(sizing_w05_nsxt_model="Dedicated - HA Cluster",3,1)), PRODUCT((IF(AND(sizing_w06_chosen="Included",sizing_w06_nsxt_model<>"Shared"),VLOOKUP(sizing_w06_nsxt_appliance_size,table_nsxt_manager_cpu,2,FALSE),0)),IF(sizing_w06_nsxt_model="Dedicated - HA Cluster",3,1)), PRODUCT((IF(AND(sizing_w07_chosen="Included",sizing_w07_nsxt_model<>"Shared"),VLOOKUP(sizing_w07_nsxt_appliance_size,table_nsxt_manager_cpu,2,FALSE),0)),IF(sizing_w07_nsxt_model="Dedicated - HA Cluster",3,1)), PRODUCT((IF(AND(sizing_w08_chosen="Included",sizing_w08_nsxt_model<>"Shared"),VLOOKUP(sizing_w08_nsxt_appliance_size,table_nsxt_manager_cpu,2,FALSE),0)),IF(sizing_w08_nsxt_model="Dedicated - HA Cluster",3,1)), PRODUCT((IF(AND(sizing_w09_chosen="Included",sizing_w09_nsxt_model<>"Shared"),VLOOKUP(sizing_w09_nsxt_appliance_size,table_nsxt_manager_cpu,2,FALSE),0)),IF(sizing_w09_nsxt_model="Dedicated - HA Cluster",3,1)), PRODUCT((IF(AND(sizing_w10_chosen="Included",sizing_w10_nsxt_model<>"Shared"),VLOOKUP(sizing_w10_nsxt_appliance_size,table_nsxt_manager_cpu,2,FALSE),0)),IF(sizing_w10_nsxt_model="Dedicated - HA Cluster",3,1)), PRODUCT((IF(AND(sizing_w11_chosen="Included",sizing_w11_nsxt_model<>"Shared"),VLOOKUP(sizing_w11_nsxt_appliance_size,table_nsxt_manager_cpu,2,FALSE),0)),IF(sizing_w11_nsxt_model="Dedicated - HA Cluster",3,1)), PRODUCT((IF(AND(sizing_w12_chosen="Included",sizing_w12_nsxt_model<>"Shared"),VLOOKUP(sizing_w12_nsxt_appliance_size,table_nsxt_manager_cpu,2,FALSE),0)),IF(sizing_w12_nsxt_model="Dedicated - HA Cluster",3,1)), PRODUCT((IF(AND(sizing_w13_chosen="Included",sizing_w13_nsxt_model<>"Shared"),VLOOKUP(sizing_w13_nsxt_appliance_size,table_nsxt_manager_cpu,2,FALSE),0)),IF(sizing_w13_nsxt_model="Dedicated - HA Cluster",3,1)), PRODUCT((IF(AND(sizing_w14_chosen="Included",sizing_w14_nsxt_model<>"Shared"),VLOOKUP(sizing_w14_nsxt_appliance_size,table_nsxt_manager_cpu,2,FALSE),0)),IF(sizing_w14_nsxt_model="Dedicated - HA Cluster",3,1)), PRODUCT((IF(AND(sizing_w15_chosen="Included",sizing_w15_nsxt_model<>"Shared"),VLOOKUP(sizing_w15_nsxt_appliance_size,table_nsxt_manager_cpu,2,FALSE),0)),IF(sizing_w15_nsxt_model="Dedicated - HA Cluster",3,1)), PRODUCT((IF(AND(sizing_w16_chosen="Included",sizing_w16_nsxt_model<>"Shared"),VLOOKUP(sizing_w16_nsxt_appliance_size,table_nsxt_manager_cpu,2,FALSE),0)),IF(sizing_w16_nsxt_model="Dedicated - HA Cluster",3,1)), PRODUCT((IF(AND(sizing_w17_chosen="Included",sizing_w17_nsxt_model<>"Shared"),VLOOKUP(sizing_w17_nsxt_appliance_size,table_nsxt_manager_cpu,2,FALSE),0)),IF(sizing_w17_nsxt_model="Dedicated - HA Cluster",3,1)), PRODUCT((IF(AND(sizing_w18_chosen="Included",sizing_w18_nsxt_model<>"Shared"),VLOOKUP(sizing_w18_nsxt_appliance_size,table_nsxt_manager_cpu,2,FALSE),0)),IF(sizing_w18_nsxt_model="Dedicated - HA Cluster",3,1)), PRODUCT((IF(AND(sizing_w19_chosen="Included",sizing_w19_nsxt_model<>"Shared"),VLOOKUP(sizing_w19_nsxt_appliance_size,table_nsxt_manager_cpu,2,FALSE),0)),IF(sizing_w19_nsxt_model="Dedicated - HA Cluster",3,1)), PRODUCT((IF(AND(sizing_w20_chosen="Included",sizing_w20_nsxt_model<>"Shared"),VLOOKUP(sizing_w20_nsxt_appliance_size,table_nsxt_manager_cpu,2,FALSE),0)),IF(sizing_w20_nsxt_model="Dedicated - HA Cluster",3,1)), PRODUCT((IF(AND(sizing_w21_chosen="Included",sizing_w21_nsxt_model<>"Shared"),VLOOKUP(sizing_w21_nsxt_appliance_size,table_nsxt_manager_cpu,2,FALSE),0)),IF(sizing_w21_nsxt_model="Dedicated - HA Cluster",3,1)), PRODUCT((IF(AND(sizing_w22_chosen="Included",sizing_w22_nsxt_model<>"Shared"),VLOOKUP(sizing_w22_nsxt_appliance_size,table_nsxt_manager_cpu,2,FALSE),0)),IF(sizing_w22_nsxt_model="Dedicated - HA Cluster",3,1)), PRODUCT((IF(AND(sizing_w23_chosen="Included",sizing_w23_nsxt_model<>"Shared"),VLOOKUP(sizing_w23_nsxt_appliance_size,table_nsxt_manager_cpu,2,FALSE),0)),IF(sizing_w23_nsxt_model="Dedicated - HA Cluster",3,1)), PRODUCT((IF(AND(sizing_w24_chosen="Included",sizing_w24_nsxt_model<>"Shared"),VLOOKUP(sizing_w24_nsxt_appliance_size,table_nsxt_manager_cpu,2,FALSE),0)),IF(sizing_w24_nsxt_model="Dedicated - HA Cluster",3,1)),'Static Reference Tables'!D71) -> 0 | L16: =SUM( PRODUCT((IF(AND(sizing_w01_chosen="Included",sizing_w01_nsxt_model<>"Shared"),VLOOKUP(sizing_w01_nsxt_appliance_size,table_nsxt_manager_ram,2,FALSE),0)),IF(sizing_w01_nsxt_model="Mandatory - HA Cluster",3,1)), PRODUCT((IF(AND(sizing_w02_chosen="Included",sizing_w02_nsxt_model<>"Shared"),VLOOKUP(sizing_w02_nsxt_appliance_size,table_nsxt_manager_ram,2,FALSE),0)),IF(sizing_w02_nsxt_model="Dedicated - HA Cluster",3,1)), PRODUCT((IF(AND(sizing_w03_chosen="Included",sizing_w03_nsxt_model<>"Shared"),VLOOKUP(sizing_w03_nsxt_appliance_size,table_nsxt_manager_ram,2,FALSE),0)),IF(sizing_w03_nsxt_model="Dedicated - HA Cluster",3,1)), PRODUCT((IF(AND(sizing_w04_chosen="Included",sizing_w04_nsxt_model<>"Shared"),VLOOKUP(sizing_w04_nsxt_appliance_size,table_nsxt_manager_ram,2,FALSE),0)),IF(sizing_w04_nsxt_model="Dedicated - HA Cluster",3,1)), PRODUCT((IF(AND(sizing_w05_chosen="Included",sizing_w05_nsxt_model<>"Shared"),VLOOKUP(sizing_w05_nsxt_appliance_size,table_nsxt_manager_ram,2,FALSE),0)),IF(sizing_w05_nsxt_model="Dedicated - HA Cluster",3,1)), PRODUCT((IF(AND(sizing_w06_chosen="Included",sizing_w06_nsxt_model<>"Shared"),VLOOKUP(sizing_w06_nsxt_appliance_size,table_nsxt_manager_ram,2,FALSE),0)),IF(sizing_w06_nsxt_model="Dedicated - HA Cluster",3,1)), PRODUCT((IF(AND(sizing_w07_chosen="Included",sizing_w07_nsxt_model<>"Shared"),VLOOKUP(sizing_w07_nsxt_appliance_size,table_nsxt_manager_ram,2,FALSE),0)),IF(sizing_w07_nsxt_model="Dedicated - HA Cluster",3,1)), PRODUCT((IF(AND(sizing_w08_chosen="Included",sizing_w08_nsxt_model<>"Shared"),VLOOKUP(sizing_w08_nsxt_appliance_size,table_nsxt_manager_ram,2,FALSE),0)),IF(sizing_w08_nsxt_model="Dedicated - HA Cluster",3,1)), PRODUCT((IF(AND(sizing_w09_chosen="Included",sizing_w09_nsxt_model<>"Shared"),VLOOKUP(sizing_w09_nsxt_appliance_size,table_nsxt_manager_ram,2,FALSE),0)),IF(sizing_w09_nsxt_model="Dedicated - HA Cluster",3,1)), PRODUCT((IF(AND(sizing_w10_chosen="Included",sizing_w10_nsxt_model<>"Shared"),VLOOKUP(sizing_w10_nsxt_appliance_size,table_nsxt_manager_ram,2,FALSE),0)),IF(sizing_w10_nsxt_model="Dedicated - HA Cluster",3,1)), PRODUCT((IF(AND(sizing_w11_chosen="Included",sizing_w11_nsxt_model<>"Shared"),VLOOKUP(sizing_w11_nsxt_appliance_size,table_nsxt_manager_ram,2,FALSE),0)),IF(sizing_w11_nsxt_model="Dedicated - HA Cluster",3,1)), PRODUCT((IF(AND(sizing_w12_chosen="Included",sizing_w12_nsxt_model<>"Shared"),VLOOKUP(sizing_w12_nsxt_appliance_size,table_nsxt_manager_ram,2,FALSE),0)),IF(sizing_w12_nsxt_model="Dedicated - HA Cluster",3,1)), PRODUCT((IF(AND(sizing_w13_chosen="Included",sizing_w13_nsxt_model<>"Shared"),VLOOKUP(sizing_w13_nsxt_appliance_size,table_nsxt_manager_ram,2,FALSE),0)),IF(sizing_w13_nsxt_model="Dedicated - HA Cluster",3,1)), PRODUCT((IF(AND(sizing_w14_chosen="Included",sizing_w14_nsxt_model<>"Shared"),VLOOKUP(sizing_w14_nsxt_appliance_size,table_nsxt_manager_ram,2,FALSE),0)),IF(sizing_w14_nsxt_model="Dedicated - HA Cluster",3,1)), PRODUCT((IF(AND(sizing_w15_chosen="Included",sizing_w15_nsxt_model<>"Shared"),VLOOKUP(sizing_w15_nsxt_appliance_size,table_nsxt_manager_ram,2,FALSE),0)),IF(sizing_w15_nsxt_model="Dedicated - HA Cluster",3,1)), PRODUCT((IF(AND(sizing_w16_chosen="Included",sizing_w16_nsxt_model<>"Shared"),VLOOKUP(sizing_w16_nsxt_appliance_size,table_nsxt_manager_ram,2,FALSE),0)),IF(sizing_w16_nsxt_model="Dedicated - HA Cluster",3,1)), PRODUCT((IF(AND(sizing_w17_chosen="Included",sizing_w17_nsxt_model<>"Shared"),VLOOKUP(sizing_w17_nsxt_appliance_size,table_nsxt_manager_ram,2,FALSE),0)),IF(sizing_w17_nsxt_model="Dedicated - HA Cluster",3,1)), PRODUCT((IF(AND(sizing_w18_chosen="Included",sizing_w18_nsxt_model<>"Shared"),VLOOKUP(sizing_w18_nsxt_appliance_size,table_nsxt_manager_ram,2,FALSE),0)),IF(sizing_w18_nsxt_model="Dedicated - HA Cluster",3,1)), PRODUCT((IF(AND(sizing_w19_chosen="Included",sizing_w19_nsxt_model<>"Shared"),VLOOKUP(sizing_w19_nsxt_appliance_size,table_nsxt_manager_ram,2,FALSE),0)),IF(sizing_w19_nsxt_model="Dedicated - HA Cluster",3,1)), PRODUCT((IF(AND(sizing_w20_chosen="Included",sizing_w20_nsxt_model<>"Shared"),VLOOKUP(sizing_w20_nsxt_appliance_size,table_nsxt_manager_ram,2,FALSE),0)),IF(sizing_w20_nsxt_model="Dedicated - HA Cluster",3,1)), PRODUCT((IF(AND(sizing_w21_chosen="Included",sizing_w21_nsxt_model<>"Shared"),VLOOKUP(sizing_w21_nsxt_appliance_size,table_nsxt_manager_ram,2,FALSE),0)),IF(sizing_w21_nsxt_model="Dedicated - HA Cluster",3,1)), PRODUCT((IF(AND(sizing_w22_chosen="Included",sizing_w22_nsxt_model<>"Shared"),VLOOKUP(sizing_w22_nsxt_appliance_size,table_nsxt_manager_ram,2,FALSE),0)),IF(sizing_w22_nsxt_model="Dedicated - HA Cluster",3,1)), PRODUCT((IF(AND(sizing_w23_chosen="Included",sizing_w23_nsxt_model<>"Shared"),VLOOKUP(sizing_w23_nsxt_appliance_size,table_nsxt_manager_ram,2,FALSE),0)),IF(sizing_w23_nsxt_model="Dedicated - HA Cluster",3,1)), PRODUCT((IF(AND(sizing_w24_chosen="Included",sizing_w24_nsxt_model<>"Shared"),VLOOKUP(sizing_w24_nsxt_appliance_size,table_nsxt_manager_ram,2,FALSE),0)),IF(sizing_w24_nsxt_model="Dedicated - HA Cluster",3,1)),'Static Reference Tables'!D72) -> 0 | M16: =SUM( PRODUCT((IF(AND(sizing_w01_chosen="Included",sizing_w01_nsxt_model<>"Shared"),VLOOKUP(sizing_w01_nsxt_appliance_size,table_nsxt_manager_disk_gb,2,FALSE),0)),IF(sizing_w01_nsxt_model="Mandatory - HA Cluster",3,1)), PRODUCT((IF(AND(sizing_w02_chosen="Included",sizing_w02_nsxt_model<>"Shared"),VLOOKUP(sizing_w02_nsxt_appliance_size,table_nsxt_manager_disk_gb,2,FALSE),0)),IF(sizing_w02_nsxt_model="Dedicated - HA Cluster",3,1)), PRODUCT((IF(AND(sizing_w03_chosen="Included",sizing_w03_nsxt_model<>"Shared"),VLOOKUP(sizing_w03_nsxt_appliance_size,table_nsxt_manager_disk_gb,2,FALSE),0)),IF(sizing_w03_nsxt_model="Dedicated - HA Cluster",3,1)), PRODUCT((IF(AND(sizing_w04_chosen="Included",sizing_w04_nsxt_model<>"Shared"),VLOOKUP(sizing_w04_nsxt_appliance_size,table_nsxt_manager_disk_gb,2,FALSE),0)),IF(sizing_w04_nsxt_model="Dedicated - HA Cluster",3,1)), PRODUCT((IF(AND(sizing_w05_chosen="Included",sizing_w05_nsxt_model<>"Shared"),VLOOKUP(sizing_w05_nsxt_appliance_size,table_nsxt_manager_disk_gb,2,FALSE),0)),IF(sizing_w05_nsxt_model="Dedicated - HA Cluster",3,1)), PRODUCT((IF(AND(sizing_w06_chosen="Included",sizing_w06_nsxt_model<>"Shared"),VLOOKUP(sizing_w06_nsxt_appliance_size,table_nsxt_manager_disk_gb,2,FALSE),0)),IF(sizing_w06_nsxt_model="Dedicated - HA Cluster",3,1)), PRODUCT((IF(AND(sizing_w07_chosen="Included",sizing_w07_nsxt_model<>"Shared"),VLOOKUP(sizing_w07_nsxt_appliance_size,table_nsxt_manager_disk_gb,2,FALSE),0)),IF(sizing_w07_nsxt_model="Dedicated - HA Cluster",3,1)), PRODUCT((IF(AND(sizing_w08_chosen="Included",sizing_w08_nsxt_model<>"Shared"),VLOOKUP(sizing_w08_nsxt_appliance_size,table_nsxt_manager_disk_gb,2,FALSE),0)),IF(sizing_w08_nsxt_model="Dedicated - HA Cluster",3,1)), PRODUCT((IF(AND(sizing_w09_chosen="Included",sizing_w09_nsxt_model<>"Shared"),VLOOKUP(sizing_w09_nsxt_appliance_size,table_nsxt_manager_disk_gb,2,FALSE),0)),IF(sizing_w09_nsxt_model="Dedicated - HA Cluster",3,1)), PRODUCT((IF(AND(sizing_w10_chosen="Included",sizing_w10_nsxt_model<>"Shared"),VLOOKUP(sizing_w10_nsxt_appliance_size,table_nsxt_manager_disk_gb,2,FALSE),0)),IF(sizing_w10_nsxt_model="Dedicated - HA Cluster",3,1)), PRODUCT((IF(AND(sizing_w11_chosen="Included",sizing_w11_nsxt_model<>"Shared"),VLOOKUP(sizing_w11_nsxt_appliance_size,table_nsxt_manager_disk_gb,2,FALSE),0)),IF(sizing_w11_nsxt_model="Dedicated - HA Cluster",3,1)), PRODUCT((IF(AND(sizing_w12_chosen="Included",sizing_w12_nsxt_model<>"Shared"),VLOOKUP(sizing_w12_nsxt_appliance_size,table_nsxt_manager_disk_gb,2,FALSE),0)),IF(sizing_w12_nsxt_model="Dedicated - HA Cluster",3,1)), PRODUCT((IF(AND(sizing_w13_chosen="Included",sizing_w13_nsxt_model<>"Shared"),VLOOKUP(sizing_w13_nsxt_appliance_size,table_nsxt_manager_disk_gb,2,FALSE),0)),IF(sizing_w13_nsxt_model="Dedicated - HA Cluster",3,1)), PRODUCT((IF(AND(sizing_w14_chosen="Included",sizing_w14_nsxt_model<>"Shared"),VLOOKUP(sizing_w14_nsxt_appliance_size,table_nsxt_manager_disk_gb,2,FALSE),0)),IF(sizing_w14_nsxt_model="Dedicated - HA Cluster",3,1)), PRODUCT((IF(AND(sizing_w15_chosen="Included",sizing_w15_nsxt_model<>"Shared"),VLOOKUP(sizing_w15_nsxt_appliance_size,table_nsxt_manager_disk_gb,2,FALSE),0)),IF(sizing_w15_nsxt_model="Dedicated - HA Cluster",3,1)), PRODUCT((IF(AND(sizing_w16_chosen="Included",sizing_w16_nsxt_model<>"Shared"),VLOOKUP(sizing_w16_nsxt_appliance_size,table_nsxt_manager_disk_gb,2,FALSE),0)),IF(sizing_w16_nsxt_model="Dedicated - HA Cluster",3,1)), PRODUCT((IF(AND(sizing_w17_chosen="Included",sizing_w17_nsxt_model<>"Shared"),VLOOKUP(sizing_w17_nsxt_appliance_size,table_nsxt_manager_disk_gb,2,FALSE),0)),IF(sizing_w17_nsxt_model="Dedicated - HA Cluster",3,1)), PRODUCT((IF(AND(sizing_w18_chosen="Included",sizing_w18_nsxt_model<>"Shared"),VLOOKUP(sizing_w18_nsxt_appliance_size,table_nsxt_manager_disk_gb,2,FALSE),0)),IF(sizing_w18_nsxt_model="Dedicated - HA Cluster",3,1)), PRODUCT((IF(AND(sizing_w19_chosen="Included",sizing_w19_nsxt_model<>"Shared"),VLOOKUP(sizing_w19_nsxt_appliance_size,table_nsxt_manager_disk_gb,2,FALSE),0)),IF(sizing_w19_nsxt_model="Dedicated - HA Cluster",3,1)), PRODUCT((IF(AND(sizing_w20_chosen="Included",sizing_w20_nsxt_model<>"Shared"),VLOOKUP(sizing_w20_nsxt_appliance_size,table_nsxt_manager_disk_gb,2,FALSE),0)),IF(sizing_w20_nsxt_model="Dedicated - HA Cluster",3,1)), PRODUCT((IF(AND(sizing_w21_chosen="Included",sizing_w21_nsxt_model<>"Shared"),VLOOKUP(sizing_w21_nsxt_appliance_size,table_nsxt_manager_disk_gb,2,FALSE),0)),IF(sizing_w21_nsxt_model="Dedicated - HA Cluster",3,1)), PRODUCT((IF(AND(sizing_w22_chosen="Included",sizing_w22_nsxt_model<>"Shared"),VLOOKUP(sizing_w22_nsxt_appliance_size,table_nsxt_manager_disk_gb,2,FALSE),0)),IF(sizing_w22_nsxt_model="Dedicated - HA Cluster",3,1)), PRODUCT((IF(AND(sizing_w23_chosen="Included",sizing_w23_nsxt_model<>"Shared"),VLOOKUP(sizing_w23_nsxt_appliance_size,table_nsxt_manager_disk_gb,2,FALSE),0)),IF(sizing_w23_nsxt_model="Dedicated - HA Cluster",3,1)), PRODUCT((IF(AND(sizing_w24_chosen="Included",sizing_w24_nsxt_model<>"Shared"),VLOOKUP(sizing_w24_nsxt_appliance_size,table_nsxt_manager_disk_gb,2,FALSE),0)),IF(sizing_w24_nsxt_model="Dedicated - HA Cluster",3,1)),,'Static Reference Tables'!D73) -> 0 | O16: Swap File Requirements | R16: =CONCATENATE(SUM(L8:L27)) -> 207
